"use strict";(self.webpackChunkzio_site=self.webpackChunkzio_site||[]).push([[35480],{3905:(e,t,n)=>{n.d(t,{Zo:()=>c,kt:()=>m});var a=n(67294);function r(e,t,n){return t in e?Object.defineProperty(e,t,{value:n,enumerable:!0,configurable:!0,writable:!0}):e[t]=n,e}function o(e,t){var n=Object.keys(e);if(Object.getOwnPropertySymbols){var a=Object.getOwnPropertySymbols(e);t&&(a=a.filter((function(t){return Object.getOwnPropertyDescriptor(e,t).enumerable}))),n.push.apply(n,a)}return n}function i(e){for(var t=1;t<arguments.length;t++){var n=null!=arguments[t]?arguments[t]:{};t%2?o(Object(n),!0).forEach((function(t){r(e,t,n[t])})):Object.getOwnPropertyDescriptors?Object.defineProperties(e,Object.getOwnPropertyDescriptors(n)):o(Object(n)).forEach((function(t){Object.defineProperty(e,t,Object.getOwnPropertyDescriptor(n,t))}))}return e}function l(e,t){if(null==e)return{};var n,a,r=function(e,t){if(null==e)return{};var n,a,r={},o=Object.keys(e);for(a=0;a<o.length;a++)n=o[a],t.indexOf(n)>=0||(r[n]=e[n]);return r}(e,t);if(Object.getOwnPropertySymbols){var o=Object.getOwnPropertySymbols(e);for(a=0;a<o.length;a++)n=o[a],t.indexOf(n)>=0||Object.prototype.propertyIsEnumerable.call(e,n)&&(r[n]=e[n])}return r}var s=a.createContext({}),p=function(e){var t=a.useContext(s),n=t;return e&&(n="function"==typeof e?e(t):i(i({},t),e)),n},c=function(e){var t=p(e.components);return a.createElement(s.Provider,{value:t},e.children)},h="mdxType",d={inlineCode:"code",wrapper:function(e){var t=e.children;return a.createElement(a.Fragment,{},t)}},u=a.forwardRef((function(e,t){var n=e.components,r=e.mdxType,o=e.originalType,s=e.parentName,c=l(e,["components","mdxType","originalType","parentName"]),h=p(n),u=r,m=h["".concat(s,".").concat(u)]||h[u]||d[u]||o;return n?a.createElement(m,i(i({ref:t},c),{},{components:n})):a.createElement(m,i({ref:t},c))}));function m(e,t){var n=arguments,r=t&&t.mdxType;if("string"==typeof e||r){var o=n.length,i=new Array(o);i[0]=u;var l={};for(var s in t)hasOwnProperty.call(t,s)&&(l[s]=t[s]);l.originalType=e,l[h]="string"==typeof e?e:r,i[1]=l;for(var p=2;p<o;p++)i[p]=n[p];return a.createElement.apply(null,i)}return a.createElement.apply(null,n)}u.displayName="MDXCreateElement"},57931:(e,t,n)=>{n.r(t),n.d(t,{assets:()=>s,contentTitle:()=>i,default:()=>d,frontMatter:()=>o,metadata:()=>l,toc:()=>p});var a=n(87462),r=(n(67294),n(3905));const o={id:"imperative-vs-declarative",title:"Imperative vs. Declarative Error Handling",sidebar_label:"Imperative vs. Declarative"},i=void 0,l={unversionedId:"reference/error-management/imperative-vs-declarative",id:"reference/error-management/imperative-vs-declarative",title:"Imperative vs. Declarative Error Handling",description:"To figure out the benefit of typed errors in declarative error handling, we need to understand the drawbacks of the imperative approach and then see how the declarative approach can be used to solve the same problem.",source:"@site/docs/reference/error-management/declarative.md",sourceDirName:"reference/error-management",slug:"/reference/error-management/imperative-vs-declarative",permalink:"/reference/error-management/imperative-vs-declarative",draft:!1,editUrl:"https://github.com/zio/zio/edit/series/2.x/docs/reference/error-management/declarative.md",tags:[],version:"current",frontMatter:{id:"imperative-vs-declarative",title:"Imperative vs. Declarative Error Handling",sidebar_label:"Imperative vs. Declarative"},sidebar:"reference-sidebar",previous:{title:"Fatal Errors",permalink:"/reference/error-management/types/fatals"},next:{title:"Expected and Unexpected Errors",permalink:"/reference/error-management/expected-and-unexpected-errors"}},s={},p=[{value:"Imperative Error Handling",id:"imperative-error-handling",level:2},{value:"Declarative Error Handling",id:"declarative-error-handling",level:2},{value:"Imperative vs. Declarative",id:"imperative-vs-declarative",level:2},{value:"Referential Transparency",id:"referential-transparency",level:3},{value:"Type-safety",id:"type-safety",level:3},{value:"Exhaustivity Checking",id:"exhaustivity-checking",level:3},{value:"Error Model",id:"error-model",level:3}],c={toc:p},h="wrapper";function d(e){let{components:t,...n}=e;return(0,r.kt)(h,(0,a.Z)({},c,n,{components:t,mdxType:"MDXLayout"}),(0,r.kt)("p",null,"To figure out the benefit of typed errors in declarative error handling, we need to understand the drawbacks of the imperative approach and then see how the declarative approach can be used to solve the same problem."),(0,r.kt)("h2",{id:"imperative-error-handling"},"Imperative Error Handling"),(0,r.kt)("p",null,"In the imperative style, when we encounter a wrong state, we throw an exception, and to handle exceptions, we have to use the ",(0,r.kt)("inlineCode",{parentName:"p"},"try"),"/",(0,r.kt)("inlineCode",{parentName:"p"},"catch")," language construct. Whenever we encounter an exception inside a ",(0,r.kt)("inlineCode",{parentName:"p"},"try")," block, the control flow will jump to the ",(0,r.kt)("inlineCode",{parentName:"p"},"catch")," block. In the catch block, we can handle the exception and decide what to do next. This is a very common pattern in imperative programming."),(0,r.kt)("p",null,"For example, we can write the ",(0,r.kt)("inlineCode",{parentName:"p"},"divide")," function like this:"),(0,r.kt)("pre",null,(0,r.kt)("code",{parentName:"pre",className:"language-scala"},'def divide(a: Int, b: Int): Int =\n  if (b == 0)\n    throw new IllegalArgumentException("Division by zero")\n  else\n    a / b\n')),(0,r.kt)("p",null,"As we know that this function throws an exception when ",(0,r.kt)("inlineCode",{parentName:"p"},"b")," is zero, so we need to handle the exception when we call this function:"),(0,r.kt)("pre",null,(0,r.kt)("code",{parentName:"pre",className:"language-scala"},"def readFromConsole: (Int, Int) = ???\n\nval (a, b) = readFromConsole\n\ntry {\n  Some(divide(a, b))\n} catch {\n  case _: IllegalArgumentException => None\n}\n")),(0,r.kt)("h2",{id:"declarative-error-handling"},"Declarative Error Handling"),(0,r.kt)("p",null,"In declarative error handling, we treat errors as values instead of throwing exceptions. So instead of breaking the flow of the program, we can return a value that represents the error. When we have a workflow of type ",(0,r.kt)("inlineCode",{parentName:"p"},"ZIO[R, E, A]"),", the ",(0,r.kt)("inlineCode",{parentName:"p"},"E")," type parameter is used to represent that our workflow may fail with an error of type ",(0,r.kt)("inlineCode",{parentName:"p"},"E"),"."),(0,r.kt)("p",null,"For example, the following program written with ZIO may fail with an error of type ",(0,r.kt)("inlineCode",{parentName:"p"},"AgeValidationException"),":"),(0,r.kt)("pre",null,(0,r.kt)("code",{parentName:"pre",className:"language-scala"},"import zio._\n\nsealed trait AgeValidationException extends Exception\ncase class NegativeAgeException(age: Int) extends AgeValidationException\ncase class IllegalAgeException(age: Int)  extends AgeValidationException\n\ndef validate(age: Int): ZIO[Any, AgeValidationException, Int] =\n  if (age < 0)\n    ZIO.fail(NegativeAgeException(age))\n  else if (age < 18)\n    ZIO.fail(IllegalAgeException(age))\n  else ZIO.succeed(age)\n")),(0,r.kt)("p",null,"We can handle errors using ",(0,r.kt)("inlineCode",{parentName:"p"},"catchAll"),"/",(0,r.kt)("inlineCode",{parentName:"p"},"catchSome")," methods instead of using ",(0,r.kt)("inlineCode",{parentName:"p"},"try"),"/",(0,r.kt)("inlineCode",{parentName:"p"},"catch")," blocks:"),(0,r.kt)("pre",null,(0,r.kt)("code",{parentName:"pre",className:"language-scala"},"validate(17).catchAll {\n  case NegativeAgeException(age) => ???\n  case IllegalAgeException(age)  => ???\n}\n")),(0,r.kt)("h2",{id:"imperative-vs-declarative"},"Imperative vs. Declarative"),(0,r.kt)("h3",{id:"referential-transparency"},"Referential Transparency"),(0,r.kt)("p",null,"We say that an expression is referentially transparent if it can be replaced with its value without changing the behavior of the program. This property helps us to reason about a program easily. Also writing tests for our programs becomes much easier."),(0,r.kt)("p",null,"Unfortunately, when we throw an exception, we lose the ability to reason about our programs. Exceptions break the referential transparency of our programs. For example, let's say we have the following function:"),(0,r.kt)("pre",null,(0,r.kt)("code",{parentName:"pre",className:"language-scala"},"def divide10By(b: Int): Option[Int] = {\n  val result = divide(10, b)\n  try {\n    Some(result)\n  } catch {\n    case _: IllegalArgumentException => None\n  }\n}\n")),(0,r.kt)("p",null,"If we call ",(0,r.kt)("inlineCode",{parentName:"p"},"divide10By(0)"),", we will get an exception (",(0,r.kt)("inlineCode",{parentName:"p"},"IllegalArgumentException"),"). Now, let's see what happens if we replace the result with its value like this:"),(0,r.kt)("pre",null,(0,r.kt)("code",{parentName:"pre",className:"language-scala"},"def divide10By(b: Int): Option[Int] = \n  try {\n    Some(divide(10, b))\n  } catch {\n    case _: IllegalArgumentException => None\n  }\n")),(0,r.kt)("p",null,"In this case, if we call ",(0,r.kt)("inlineCode",{parentName:"p"},"divide10By(0)"),", we will get the ",(0,r.kt)("inlineCode",{parentName:"p"},"None")," value. The behavior of the function will be changed. We cannot reason about the behavior of our program by substituting expressions with their values. In this style of error handling, the behavior of the program is dependent on where we call our expressions, inside or outside the ",(0,r.kt)("inlineCode",{parentName:"p"},"try")," block."),(0,r.kt)("p",null,"When we model our programs with the ",(0,r.kt)("inlineCode",{parentName:"p"},"ZIO"),", we sure that our programs are referentially transparent. We can reason about our programs very easily without having to worry about changing the behavior of our programs."),(0,r.kt)("h3",{id:"type-safety"},"Type-safety"),(0,r.kt)("p",null,"There is no way to know what errors can be thrown by looking at the function signature. The only way to find out in which circumstance a method may throw an exception is to read and investigate its implementation. So the compiler cannot prevent us from writing unsafe codes. It is also hard for a developer to read the documentation event through reading the documentation is not sufficient as it may be obsolete, or it may don't reflect the exact exceptions."),(0,r.kt)("p",null,"In ZIO when we see the type of the effect, we can determine what kind of error it can fail with. This helps us to have compile-time type-safety on our programs not only on success values but also on failure values."),(0,r.kt)("h3",{id:"exhaustivity-checking"},"Exhaustivity Checking"),(0,r.kt)("p",null,"When we use ",(0,r.kt)("inlineCode",{parentName:"p"},"try"),"/",(0,r.kt)("inlineCode",{parentName:"p"},"catch")," the compiler doesn't know about errors at compile time, so if we forgot to handle one of the exceptions the compiler doesn't help us to write total functions. This code will crash at runtime because we forgot to handle the ",(0,r.kt)("inlineCode",{parentName:"p"},"IllegalAgeException")," case:"),(0,r.kt)("pre",null,(0,r.kt)("code",{parentName:"pre",className:"language-scala"},"try {\n  validate(17)\n} catch {\n  case NegativeAgeException(age) => ???\n  //  case IllegalAgeException(age) => ???\n}\n")),(0,r.kt)("p",null,"When we are using typed errors we can have exhaustive checking support from the compiler. For example, when we are catching all errors if we forgot to handle one of the cases, the compiler warns us about that:"),(0,r.kt)("pre",null,(0,r.kt)("code",{parentName:"pre",className:"language-scala"},"validate(17).catchAll {\n  case NegativeAgeException(age) => ???\n}\n\n// match may not be exhaustive.\n// It would fail on the following input: IllegalAgeException(_)\n")),(0,r.kt)("p",null,"In the example above, if we only handle ",(0,r.kt)("inlineCode",{parentName:"p"},"NegativeAgeException"),", the compiler will complain about the ",(0,r.kt)("inlineCode",{parentName:"p"},"IllegalAgeException")," being unhandled. This helps us cover all cases and write ",(0,r.kt)("em",{parentName:"p"},"total functions")," easily."),(0,r.kt)("blockquote",null,(0,r.kt)("p",{parentName:"blockquote"},(0,r.kt)("strong",{parentName:"p"},"Note:")),(0,r.kt)("p",{parentName:"blockquote"},"When a function is defined for all possible input values, it is called a ",(0,r.kt)("em",{parentName:"p"},"total function")," in functional programming.")),(0,r.kt)("h3",{id:"error-model"},"Error Model"),(0,r.kt)("p",null,"The error model based on the ",(0,r.kt)("inlineCode",{parentName:"p"},"try"),"/",(0,r.kt)("inlineCode",{parentName:"p"},"catch"),"/",(0,r.kt)("inlineCode",{parentName:"p"},"finally")," statement is lossy and broken. Because if we have the combinations of these statements we can throw many exceptions, and then we are only able to catch one of them. All the other ones are lost. They are swallowed into a black hole, and also the one that we catch is the wrong one. It is not the primary cause of the failure."),(0,r.kt)("p",null,"To be more specific, if the ",(0,r.kt)("inlineCode",{parentName:"p"},"try")," block throws an exception, and the ",(0,r.kt)("inlineCode",{parentName:"p"},"finally")," block throws an exception as well, then, if these are caught at a higher level, only the finalizer's exception will be caught normally, not the exception from the try block."),(0,r.kt)("p",null,"In the following example, we are going to show this behavior:"),(0,r.kt)("pre",null,(0,r.kt)("code",{parentName:"pre",className:"language-scala"},' try {\n    try throw new Error("e1")\n    finally throw new Error("e2")\n } catch {\n   case e: Error => println(e)\n }\n\n// Output:\n// e2\n')),(0,r.kt)("p",null,"The above program just prints the ",(0,r.kt)("inlineCode",{parentName:"p"},"e2")," while it is not the primary cause of failure. That is why we say the ",(0,r.kt)("inlineCode",{parentName:"p"},"try"),"/",(0,r.kt)("inlineCode",{parentName:"p"},"catch")," model is lossy."),(0,r.kt)("p",null,"In ZIO, all the errors will still be reported. So even though we are only able to catch one error, the other ones will be reported which we have full control over them. They don't get lost."),(0,r.kt)("p",null,"Let's write a ZIO version:"),(0,r.kt)("pre",null,(0,r.kt)("code",{parentName:"pre",className:"language-scala"},'ZIO.fail("e1")\n  .ensuring(ZIO.succeed(throw new Exception("e2")))\n  .catchAll {\n    case "e1" => Console.printLine("e1")\n    case "e2" => Console.printLine("e2")\n  }\n\n// Output:\n// e1\n')),(0,r.kt)("p",null,"ZIO guarantees that no errors are lost. It has a ",(0,r.kt)("em",{parentName:"p"},"lossless error model"),". This guarantee is provided via a hierarchy of supervisors and information made available via data types such as ",(0,r.kt)("inlineCode",{parentName:"p"},"Exit")," and ",(0,r.kt)("inlineCode",{parentName:"p"},"Cause"),". All errors will be reported. If there's a bug in the code, ZIO enables us to find out about it."))}d.isMDXComponent=!0}}]);